<?xml version="1.0"?>
<robot xmlns:xacro="http://ros.org/wiki/xacro">

  <xacro:include filename="$(find robot_description)/urdf/leg_servo/leg_servo.transmission.xacro"/>
  <xacro:include filename="$(find robot_description)/urdf/leg_servo/leg_servo.gazebo.xacro"/>
  
  <xacro:macro name="leg_servo_v0" params="prefix parent *joint_origin *joint_axis">
	<joint name="${prefix}_leg_servo_joint" type="revolute">
	  <xacro:insert_block name="joint_origin"/>
	  <parent link="${parent}"/>
	  <child link="${prefix}_leg_servo_link"/>
          <limit effort="500" velocity="10" lower="-3" upper = "3"/>
          <dynamics damping="0.005" friction="0.1"/>
	  <xacro:insert_block name="joint_axis"/>
	</joint>

	<link name="${prefix}_leg_servo_link">
	  <visual>
		<geometry>
		  <mesh filename="package://robot_description/meshes/DAE/leg_servo/leg_servo.dae"/>
		</geometry>
	  </visual>
	  <collision>
		<geometry>
		  <mesh filename="package://robot_description/meshes/STL/leg_servo/leg_servo.stl"/>
		</geometry>
	  </collision>
	  <inertial>
		<origin xyz="0.016735 0 0"/>
		<mass value="0.09"/>
		<inertia ixx="0.0001" ixy="0" ixz="0" iyy="0.00024" iyz="0" izz="0.00028" /> izz="0.012" -->
	  </inertial>
	</link>
  </xacro:macro>
  
</robot>
