<?xml version="1.0"?>
<robot xmlns:xacro="http://ros.org/wiki/xacro">

  <xacro:include filename="$(find robot_description)/urdf/leg_link2/leg_link2.transmission.xacro"/>
  <xacro:include filename="$(find robot_description)/urdf/leg_link2/leg_link2.gazebo.xacro"/>
  
  <xacro:macro name="leg_link2_v0" params="prefix parent *joint_origin *joint_axis">
	<joint name="${prefix}_leg_link2_joint" type="revolute">
	  <xacro:insert_block name="joint_origin"/>
	  <parent link="${parent}"/>
	  <child link="${prefix}_leg_link2_link"/>
          <limit effort="50" velocity="10" lower="-6.28" upper = "6.28"/>
          <dynamics damping="0.005" friction="0.1"/>
	  <xacro:insert_block name="joint_axis"/>
	</joint>

	<link name="${prefix}_leg_link2_link">
	  <visual>
		<geometry>
		  <mesh filename="package://robot_description/meshes/DAE/leg_link2/leg_link2.dae"/>
		</geometry>
	  </visual>
	  <collision>
		<geometry>
		  <mesh filename="package://robot_description/meshes/STL/leg_link2/leg_link2.stl"/>
		</geometry>
	  </collision>
	  <inertial>
		<origin xyz="0.0116 0 -0.0196"/>
		<mass value="0.02"/>
		<inertia ixx="0.00002" ixy="0" ixz="-0.00000022" iyy="0.00002" iyz="0" izz="0.0000009" />
	  </inertial>
	</link>
  </xacro:macro>
  
</robot>
