<?xml version="1.0"?>
<robot xmlns:xacro="http://ros.org/wiki/xacro">

  <xacro:include filename="$(find robot_description)/urdf/leg_link1/leg_link1.transmission.xacro"/>
  <xacro:include filename="$(find robot_description)/urdf/leg_link1/leg_link1.gazebo.xacro"/>
  
  <xacro:macro name="leg_link1_v0" params="prefix parent *joint_origin *joint_axis">
	<joint name="${prefix}_leg_link1_joint" type="revolute">
	  <xacro:insert_block name="joint_origin"/>
	  <parent link="${parent}"/>
	  <child link="${prefix}_leg_link1_link"/>
          <limit effort="50" velocity="10" lower="-6.28" upper = "6.28"/>
          <dynamics damping="0.005" friction="0.1"/>
	  <xacro:insert_block name="joint_axis"/>
	</joint>

	<link name="${prefix}_leg_link1_link">
	  <visual>
		<geometry>
		  <mesh filename="package://robot_description/meshes/DAE/leg_link1/leg_link1.dae"/>
		</geometry>
	  </visual>
	  <collision>
		<geometry>
		  <mesh filename="package://robot_description/meshes/STL/leg_link1/leg_link1.stl"/>
		</geometry>
	  </collision>
	  <inertial>
		<origin xyz="0.0225 0 0"/>
		<mass value="0.0256"/>
		<inertia ixx="0.000000612" ixy="0" ixz="0" iyy="0.000004761" iyz="0" izz="0.000005218" />
	  </inertial>
	</link>
  </xacro:macro>
  
</robot>
